<?xml version="1.0"?>

<robot name="FourDOF">

  <link name="world">
  </link>

  <link name="link1">
    <visual>
      <origin xyz="0 0 0.2" rpy="0 0 0"/>
      <geometry>
        <cylinder length="0.4" radius="0.02"/>
      </geometry>
      <material name="orange"/>
    </visual>
  </link>

  <link name="link2">
    <visual>
      <origin xyz="0 0.2 0" rpy="1.57 0 0"/>
      <geometry>
        <cylinder length="0.4" radius="0.02"/>
      </geometry>
      <material name="red"/>
    </visual>
  </link>

  <link name="link3">
    <visual>
      <origin xyz="0 0 -0.2" rpy="0 0 0"/>
      <geometry>
        <cylinder length="0.4" radius="0.02"/>
      </geometry>
      <material name="blue"/>
    </visual>
  </link>

  <link name="link4">
    <visual>
      <origin xyz="0 0.2 0" rpy="1.57 0 0"/>
      <geometry>
        <cylinder length="0.4" radius="0.02"/>
      </geometry>
      <material name="yellow"/>
    </visual>
  </link>

  <link name="tip">
    <visual>
      <origin xyz="0 0 0" rpy="0 0 0"/>
      <geometry>
        <box size="0.1 0.1 0.1"/>
      </geometry>
      <material name="yellow"/>
    </visual>
  </link>

  <joint name="base" type="fixed">
    <parent link="world"/>
    <child link="link1"/>
    <origin xyz="0 0 0" rpy="0 0 0"/>
  </joint>

  <joint name="theta1" type="continuous">
    <parent link="link1"/>
    <child link="link2"/>
    <origin xyz="0 0 0.4" rpy="0 0 0"/> 
    <axis xyz="0 0 1"/>  
    <limit lower="-4" upper="4" effort="99" velocity="1"/>
  </joint>

  <joint name="theta2" type="continuous">
    <parent link="link2"/>
    <child link="link3"/>
    <origin xyz="0 0.4 0" rpy="0 0 0"/>  
    <axis xyz="0 1 0"/>  
    <limit lower="-4" upper="4" effort="99" velocity="1"/>
  </joint>

  <joint name="theta3" type="continuous">
    <parent link="link3"/>
    <child link="link4"/>
    <origin xyz="0 0 -0.4" rpy="0 0 0"/>  
    <axis xyz="0 0 -1"/>  
    <limit lower="-4" upper="4" effort="99" velocity="1"/>
  </joint>

  <joint name="theta4" type="continuous">
    <parent link="link4"/>
    <child link="tip"/>
    <origin xyz="0 0.4 0" rpy="0 0 0"/> 
    <axis xyz="0 1 0"/>  
    <limit lower="-4" upper="4" effort="99" velocity="1"/>
  </joint>

  <!-- *************************************************** -->
  <!-- *********** Material Definitions ************ -->
  <!-- *************************************************** -->

  <material name="orange">
    <color rgba="1.0 0.5 0.0 1"/>
  </material>

  <material name="red">
    <color rgba="1.0 0.0 0.0 1"/>
  </material>

  <material name="blue">
    <color rgba="0.0 0.0 1.0 1"/>
  </material>

  <material name="yellow">
    <color rgba="1.0 1.0 0.0 1"/>
  </material>

</robot>
